Workbook

Sheet Overview
B2: Institutional Logics — Human vs. AI Coder Agreement (multi-report study)
B3: 3 annual reports, each coded independently by a human coder and the AI pipeline.
B5: Method
B6: Chunk matching | D6: Exact match on chunk text, matched in row order, per report (handles repeated text).
B7: Weighting | D7: Within each applicable element, the primary (top-1) logic scores 2 points and the secondary (top-2) logic scores 1 point, summed across the 5 elements.
B8: Chunk inclusion | D8: A chunk counts as "coded" by a coder if that coder marked ≥1 of the 5 elements applicable; only chunks coded by BOTH coders enter the agreement analysis.
B9: Agreement score | D9: One observation per chunk: each coder’s "dominant logic" (highest weighted-point total among PS/DS/PPG/SC). PS/DS/PPG/SC are NOMINAL categories with no established ordering, so the primary statistic is standard (unweighted) Cohen’s kappa. An earlier ordinal-weighted version is retired and kept only for comparison (see each Agreement sheet).
B10: Alternative (flexible) | D10: A separate, chunk-flexible agreement measure — see the "Flexible Agreement" sheet — credits a chunk as matching if either coder’s dominant pick was at least the other coder’s own secondary emphasis for that chunk, with chance estimated by permutation rather than a closed-form formula.
B11: Pooling | D11: The pooled confusion matrix sums each report’s own matrix; pooled kappa is recomputed from that pooled matrix (kappa is not linear, so averaging per-report kappas would not equal it).
B14: Per-report agreement
B15: Report | C15: N (coded by both) | D15: κ standard (primary) | E15: κ quadratic (retired) | F15: κ linear (retired) | G15: Raw agreement
B16: 363466802_2021 | C16: ='R1 Agreement'!G13 | D16: ='R1 Agreement'!G29 | E16: ='R1 Agreement'!G38 | F16: ='R1 Agreement'!G47 | G16: ='R1 Agreement'!G21
B17: 382023395_2022 | C17: ='R2 Agreement'!G13 | D17: ='R2 Agreement'!G29 | E17: ='R2 Agreement'!G38 | F17: ='R2 Agreement'!G47 | G17: ='R2 Agreement'!G21
B18: 25-1650208_2021 | C18: ='R3 Agreement'!G13 | D18: ='R3 Agreement'!G29 | E18: ='R3 Agreement'!G38 | F18: ='R3 Agreement'!G47 | G18: ='R3 Agreement'!G21
B19: POOLED (all reports) | C19: ='Pooled Agreement'!G11 | D19: ='Pooled Agreement'!G27 | E19: ='Pooled Agreement'!G36 | F19: ='Pooled Agreement'!G45 | G19: ='Pooled Agreement'!G19
B39: See the "Pooled Agreement" sheet for the full pooled confusion matrix and all three weighting schemes, and each report’s own "<code> Agreement" sheet for its individual confusion matrix. "Report Key" maps R1/R2/R3 codes to full report IDs.

Sheet R1 Chunk-level
A1: Chunk ID | B1: Text | C1: Human # applic. | D1: AI # applic. | E1: Human # incompl. | F1: AI # incompl. | G1: Coded by both? | H1: Human pts PS | I1: Human pts DS | J1: Human pts PPG | K1: Human pts SC | L1: AI pts PS | M1: AI pts DS | N1: AI pts PPG | O1: AI pts SC | P1: Human % PS | Q1: Human % DS | R1: Human % PPG | S1: Human % SC | T1: AI % PS | U1: AI % DS | V1: AI % PPG | W1: AI % SC
A2: 3 | B2: 2021 ANNUAL REPORT | C2: 0 | D2: 0 | E2: 0 | F2: 0 | G2: FALSE | H2: 0 | I2: 0 | J2: 0 | K2: 0 | L2: 0 | M2: 0 | N2: 0 | O2: 0 | P2: =IF(SUM(H2:K2)=0,"",H2/SUM(H2:K2)) | Q2: =IF(SUM(H2:K2)=0,"",I2/SUM(H2:K2)) | R2: =IF(SUM(H2:K2)=0,"",J2/SUM(H2:K2)) | S2: =IF(SUM(H2:K2)=0,"",K2/SUM(H2:K2)) | T2: =IF(SUM(L2:O2)=0,"",L2/SUM(L2:O2)) | U2: =IF(SUM(L2:O2)=0,"",M2/SUM(L2:O2)) | V2: =IF(SUM(L2:O2)=0,"",N2/SUM(L2:O2)) | W2: =IF(SUM(L2:O2)=0,"",O2/SUM(L2:O2))
A3: 4 | B3: I AM BECAUSE YOU ARE. | C3: 1 | D3: 1 | E3: 0 | F3: 0 | G3: TRUE | H3: 0 | I3: 0 | J3: 0 | K3: 2 | L3: 0 | M3: 0 | N3: 1 | O3: 2 | P3: =IF(SUM(H3:K3)=0,"",H3/SUM(H3:K3)) | Q3: =IF(SUM(H3:K3)=0,"",I3/SUM(H3:K3)) | R3: =IF(SUM(H3:K3)=0,"",J3/SUM(H3:K3)) | S3: =IF(SUM(H3:K3)=0,"",K3/SUM(H3:K3)) | T3: =IF(SUM(L3:O3)=0,"",L3/SUM(L3:O3)) | U3: =IF(SUM(L3:O3)=0,"",M3/SUM(L3:O3)) | V3: =IF(SUM(L3:O3)=0,"",N3/SUM(L3:O3)) | W3: =IF(SUM(L3:O3)=0,"",O3/SUM(L3:O3))
A4: 5 | B4: Friends of [community_foundation_tag], | C4: 0 | D4: 0 | E4: 0 | F4: 0 | G4: FALSE | H4: 0 | I4: 0 | J4: 0 | K4: 0 | L4: 0 | M4: 0 | N4: 0 | O4: 0 | P4: =IF(SUM(H4:K4)=0,"",H4/SUM(H4:K4)) | Q4: =IF(SUM(H4:K4)=0,"",I4/SUM(H4:K4)) | R4: =IF(SUM(H4:K4)=0,"",J4/SUM(H4:K4)) | S4: =IF(SUM(H4:K4)=0,"",K4/SUM(H4:K4)) | T4: =IF(SUM(L4:O4)=0,"",L4/SUM(L4:O4)) | U4: =IF(SUM(L4:O4)=0,"",M4/SUM(L4:O4)) | V4: =IF(SUM(L4:O4)=0,"",N4/SUM(L4:O4)) | W4: =IF(SUM(L4:O4)=0,"",O4/SUM(L4:O4))
A5: 6 | B5: I am celebrating my first anniversary at [community_foundation_tag]. | C5: 0 | D5: 0 | E5: 0 | F5: 0 | G5: FALSE | H5: 0 | I5: 0 | J5: 0 | K5: 0 | L5: 0 | M5: 0 | N5: 0 | O5: 0 | P5: =IF(SUM(H5:K5)=0,"",H5/SUM(H5:K5)) | Q5: =IF(SUM(H5:K5)=0,"",I5/SUM(H5:K5)) | R5: =IF(SUM(H5:K5)=0,"",J5/SUM(H5:K5)) | S5: =IF(SUM(H5:K5)=0,"",K5/SUM(H5:K5)) | T5: =IF(SUM(L5:O5)=0,"",L5/SUM(L5:O5)) | U5: =IF(SUM(L5:O5)=0,"",M5/SUM(L5:O5)) | V5: =IF(SUM(L5:O5)=0,"",N5/SUM(L5:O5)) | W5: =IF(SUM(L5:O5)=0,"",O5/SUM(L5:O5))
A6: 7 | B6: The fullness of this experience is beyond what I anticipated. | C6: 0 | D6: 0 | E6: 0 | F6: 0 | G6: FALSE | H6: 0 | I6: 0 | J6: 0 | K6: 0 | L6: 0 | M6: 0 | N6: 0 | O6: 0 | P6: =IF(SUM(H6:K6)=0,"",H6/SUM(H6:K6)) | Q6: =IF(SUM(H6:K6)=0,"",I6/SUM(H6:K6)) | R6: =IF(SUM(H6:K6)=0,"",J6/SUM(H6:K6)) | S6: =IF(SUM(H6:K6)=0,"",K6/SUM(H6:K6)) | T6: =IF(SUM(L6:O6)=0,"",L6/SUM(L6:O6)) | U6: =IF(SUM(L6:O6)=0,"",M6/SUM(L6:O6)) | V6: =IF(SUM(L6:O6)=0,"",N6/SUM(L6:O6)) | W6: =IF(SUM(L6:O6)=0,"",O6/SUM(L6:O6))
A7: 8 | B7: I've called Evanston my home for some time now, but I've been amazed by the depth and breadth of meaningful work and generosity happening these past couple of years. | C7: 0 | D7: 1 | E7: 0 | F7: 0 | G7: FALSE | H7: 0 | I7: 0 | J7: 0 | K7: 0 | L7: 2 | M7: 0 | N7: 0 | O7: 1 | P7: =IF(SUM(H7:K7)=0,"",H7/SUM(H7:K7)) | Q7: =IF(SUM(H7:K7)=0,"",I7/SUM(H7:K7)) | R7: =IF(SUM(H7:K7)=0,"",J7/SUM(H7:K7)) | S7: =IF(SUM(H7:K7)=0,"",K7/SUM(H7:K7)) | T7: =IF(SUM(L7:O7)=0,"",L7/SUM(L7:O7)) | U7: =IF(SUM(L7:O7)=0,"",M7/SUM(L7:O7)) | V7: =IF(SUM(L7:O7)=0,"",N7/SUM(L7:O7)) | W7: =IF(SUM(L7:O7)=0,"",O7/SUM(L7:O7))
A8: 9 | B8: This work [community_foundation_tag] do together exemplifies the true meaning of philanthropy, which is rooted in 'the love of humanity.' That's why I've been viewing [community_foundation_tag]'s work through the lens of 'Ubuntu'-a term used by the Bantu people of Southern Africa-which means 'I am because you are.' | C8: 1 | D8: 2 | E8: 0 | F8: 0 | G8: TRUE | H8: 0 | I8: 0 | J8: 0 | K8: 2 | L8: 1 | M8: 0 | N8: 1 | O8: 4 | P8: =IF(SUM(H8:K8)=0,"",H8/SUM(H8:K8)) | Q8: =IF(SUM(H8:K8)=0,"",I8/SUM(H8:K8)) | R8: =IF(SUM(H8:K8)=0,"",J8/SUM(H8:K8)) | S8: =IF(SUM(H8:K8)=0,"",K8/SUM(H8:K8)) | T8: =IF(SUM(L8:O8)=0,"",L8/SUM(L8:O8)) | U8: =IF(SUM(L8:O8)=0,"",M8/SUM(L8:O8)) | V8: =IF(SUM(L8:O8)=0,"",N8/SUM(L8:O8)) | W8: =IF(SUM(L8:O8)=0,"",O8/SUM(L8:O8))
A9: 10 | B9: I am strong because you are strong. I am weak when you are weak. | C9: 1 | D9: 1 | E9: 1 | F9: 0 | G9: TRUE | H9: 0 | I9: 0 | J9: 0 | K9: 0 | L9: 0 | M9: 0 | N9: 1 | O9: 2 | P9: =IF(SUM(H9:K9)=0,"",H9/SUM(H9:K9)) | Q9: =IF(SUM(H9:K9)=0,"",I9/SUM(H9:K9)) | R9: =IF(SUM(H9:K9)=0,"",J9/SUM(H9:K9)) | S9: =IF(SUM(H9:K9)=0,"",K9/SUM(H9:K9)) | T9: =IF(SUM(L9:O9)=0,"",L9/SUM(L9:O9)) | U9: =IF(SUM(L9:O9)=0,"",M9/SUM(L9:O9)) | V9: =IF(SUM(L9:O9)=0,"",N9/SUM(L9:O9)) | W9: =IF(SUM(L9:O9)=0,"",O9/SUM(L9:O9))
A10: 11 | B10: If my neighbor is hungry, needs shelter or clothing, and cannot thrive, then I am not whole. | C10: 1 | D10: 1 | E10: 0 | F10: 0 | G10: TRUE | H10: 0 | I10: 0 | J10: 0 | K10: 2 | L10: 0 | M10: 0 | N10: 1 | O10: 2 | P10: =IF(SUM(H10:K10)=0,"",H10/SUM(H10:K10)) | Q10: =IF(SUM(H10:K10)=0,"",I10/SUM(H10:K10)) | R10: =IF(SUM(H10:K10)=0,"",J10/SUM(H10:K10)) | S10: =IF(SUM(H10:K10)=0,"",K10/SUM(H10:K10)) | T10: =IF(SUM(L10:O10)=0,"",L10/SUM(L10:O10)) | U10: =IF(SUM(L10:O10)=0,"",M10/SUM(L10:O10)) | V10: =IF(SUM(L10:O10)=0,"",N10/SUM(L10:O10)) | W10: =IF(SUM(L10:O10)=0,"",O10/SUM(L10:O10))
A11: 12 | B11: The Ubuntu philosophy links and weaves all of us together inextricably. | C11: 2 | D11: 1 | E11: 0 | F11: 0 | G11: TRUE | H11: 0 | I11: 0 | J11: 0 | K11: 4 | L11: 0 | M11: 0 | N11: 1 | O11: 2 | P11: =IF(SUM(H11:K11)=0,"",H11/SUM(H11:K11)) | Q11: =IF(SUM(H11:K11)=0,"",I11/SUM(H11:K11)) | R11: =IF(SUM(H11:K11)=0,"",J11/SUM(H11:K11)) | S11: =IF(SUM(H11:K11)=0,"",K11/SUM(H11:K11)) | T11: =IF(SUM(L11:O11)=0,"",L11/SUM(L11:O11)) | U11: =IF(SUM(L11:O11)=0,"",M11/SUM(L11:O11)) | V11: =IF(SUM(L11:O11)=0,"",N11/SUM(L11:O11)) | W11: =IF(SUM(L11:O11)=0,"",O11/SUM(L11:O11))
A12: 13 | B12: In this report, you will read about Evanstonians who partner with [community_foundation_tag] and who embody Ubuntu in their work and personal lives. | C12: 1 | D12: 1 | E12: 0 | F12: 0 | G12: TRUE | H12: 0 | I12: 0 | J12: 0 | K12: 2 | L12: 1 | M12: 0 | N12: 0 | O12: 2 | P12: =IF(SUM(H12:K12)=0,"",H12/SUM(H12:K12)) | Q12: =IF(SUM(H12:K12)=0,"",I12/SUM(H12:K12)) | R12: =IF(SUM(H12:K12)=0,"",J12/SUM(H12:K12)) | S12: =IF(SUM(H12:K12)=0,"",K12/SUM(H12:K12)) | T12: =IF(SUM(L12:O12)=0,"",L12/SUM(L12:O12)) | U12: =IF(SUM(L12:O12)=0,"",M12/SUM(L12:O12)) | V12: =IF(SUM(L12:O12)=0,"",N12/SUM(L12:O12)) | W12: =IF(SUM(L12:O12)=0,"",O12/SUM(L12:O12))
A13: 14 | B13: These individuals are made stronger through their support of their neighbors. | C13: 1 | D13: 1 | E13: 0 | F13: 0 | G13: TRUE | H13: 0 | I13: 0 | J13: 0 | K13: 2 | L13: 1 | M13: 0 | N13: 0 | O13: 2 | P13: =IF(SUM(H13:K13)=0,"",H13/SUM(H13:K13)) | Q13: =IF(SUM(H13:K13)=0,"",I13/SUM(H13:K13)) | R13: =IF(SUM(H13:K13)=0,"",J13/SUM(H13:K13)) | S13: =IF(SUM(H13:K13)=0,"",K13/SUM(H13:K13)) | T13: =IF(SUM(L13:O13)=0,"",L13/SUM(L13:O13)) | U13: =IF(SUM(L13:O13)=0,"",M13/SUM(L13:O13)) | V13: =IF(SUM(L13:O13)=0,"",N13/SUM(L13:O13)) | W13: =IF(SUM(L13:O13)=0,"",O13/SUM(L13:O13))
... A338: 403 | B338: *2021 audited financial statements will be available for review at [community_foundation_tag], and at [community_foundation_tag]'s office in August 2022. | C338: 0 | D338: 0 | E338: 0 | F338: 0 | G338: FALSE | H338: 0 | I338: 0 | J338: 0 | K338: 0 | L338: 0 | M338: 0 | N338: 0 | O338: 0 | P338: =IF(SUM(H338:K338)=0,"",H338/SUM(H338:K338)) | Q338: =IF(SUM(H338:K338)=0,"",I338/SUM(H338:K338)) | R338: =IF(SUM(H338:K338)=0,"",J338/SUM(H338:K338)) | S338: =IF(SUM(H338:K338)=0,"",K338/SUM(H338:K338)) | T338: =IF(SUM(L338:O338)=0,"",L338/SUM(L338:O338)) | U338: =IF(SUM(L338:O338)=0,"",M338/SUM(L338:O338)) | V338: =IF(SUM(L338:O338)=0,"",N338/SUM(L338:O338)) | W338: =IF(SUM(L338:O338)=0,"",O338/SUM(L338:O338))

Sheet R1 Doc Aggregate
B2: Document-level totals — 363466802_2021
B4: Logic | C4: Human points | D4: Human % | E4: AI points | F4: AI %
B5: PS — Philanthropic Stewardship | C5: =SUMIFS('R1 Chunk-level'!H2:H338,'R1 Chunk-level'!G2:G338,TRUE) | D5: =IF($C$9=0,"",C5/$C$9) | E5: =SUMIFS('R1 Chunk-level'!L2:L338,'R1 Chunk-level'!G2:G338,TRUE) | F5: =IF($E$9=0,"",E5/$E$9)
B6: DS — Donor Services | C6: =SUMIFS('R1 Chunk-level'!I2:I338,'R1 Chunk-level'!G2:G338,TRUE) | D6: =IF($C$9=0,"",C6/$C$9) | E6: =SUMIFS('R1 Chunk-level'!M2:M338,'R1 Chunk-level'!G2:G338,TRUE) | F6: =IF($E$9=0,"",E6/$E$9)
B7: PPG — Public-Private Governance | C7: =SUMIFS('R1 Chunk-level'!J2:J338,'R1 Chunk-level'!G2:G338,TRUE) | D7: =IF($C$9=0,"",C7/$C$9) | E7: =SUMIFS('R1 Chunk-level'!N2:N338,'R1 Chunk-level'!G2:G338,TRUE) | F7: =IF($E$9=0,"",E7/$E$9)
B8: SC — Social Change | C8: =SUMIFS('R1 Chunk-level'!K2:K338,'R1 Chunk-level'!G2:G338,TRUE) | D8: =IF($C$9=0,"",C8/$C$9) | E8: =SUMIFS('R1 Chunk-level'!O2:O338,'R1 Chunk-level'!G2:G338,TRUE) | F8: =IF($E$9=0,"",E8/$E$9)
B9: Total | C9: =SUM(C5:C8) | E9: =SUM(E5:E8)

Sheet R1 Chunk Dominant
A1: Chunk ID | B1: Human dominant | C1: Human tie? | D1: AI dominant | E1: AI tie? | F1: Match?
A2: 4 | B2: SC | C2: FALSE | D2: SC | E2: FALSE | F2: TRUE
A3: 9 | B3: SC | C3: FALSE | D3: SC | E3: FALSE | F3: TRUE
A4: 10 | B4: PS | C4: TRUE | D4: SC | E4: FALSE | F4: FALSE
A5: 11 | B5: SC | C5: FALSE | D5: SC | E5: FALSE | F5: TRUE
A6: 12 | B6: SC | C6: FALSE | D6: SC | E6: FALSE | F6: TRUE
A7: 13 | B7: SC | C7: FALSE | D7: SC | E7: FALSE | F7: TRUE
A8: 14 | B8: SC | C8: FALSE | D8: SC | E8: FALSE | F8: TRUE
A9: 22 | B9: SC | C9: FALSE | D9: PS | E9: FALSE | F9: FALSE
A10: 23 | B10: SC | C10: FALSE | D10: PS | E10: FALSE | F10: FALSE
A11: 31 | B11: SC | C11: FALSE | D11: SC | E11: FALSE | F11: TRUE
A12: 32 | B12: SC | C12: FALSE | D12: SC | E12: FALSE | F12: TRUE
A13: 33 | B13: SC | C13: FALSE | D13: SC | E13: FALSE | F13: TRUE
... A162: 400 | B162: PS | C162: FALSE | D162: PS | E162: FALSE | F162: TRUE

Sheet R1 Agreement
B2: Chunk-level agreement — 363466802_2021
B3: N=161 chunks coded by both coders. Ties: 7 human, 3 AI (broken PS>DS>PPG>SC).
B7: A. Full sample
C8: AI: PS | D8: AI: DS | E8: AI: PPG | F8: AI: SC | G8: Row total
B9: Human: PS | C9: =COUNTIFS('R1 Chunk Dominant'!$B$2:$B$162,"PS",'R1 Chunk Dominant'!$D$2:$D$162,"PS") | D9: =COUNTIFS('R1 Chunk Dominant'!$B$2:$B$162,"PS",'R1 Chunk Dominant'!$D$2:$D$162,"DS") | E9: =COUNTIFS('R1 Chunk Dominant'!$B$2:$B$162,"PS",'R1 Chunk Dominant'!$D$2:$D$162,"PPG") | F9: =COUNTIFS('R1 Chunk Dominant'!$B$2:$B$162,"PS",'R1 Chunk Dominant'!$D$2:$D$162,"SC") | G9: =SUM(C9:F9)
B10: Human: DS | C10: =COUNTIFS('R1 Chunk Dominant'!$B$2:$B$162,"DS",'R1 Chunk Dominant'!$D$2:$D$162,"PS") | D10: =COUNTIFS('R1 Chunk Dominant'!$B$2:$B$162,"DS",'R1 Chunk Dominant'!$D$2:$D$162,"DS") | E10: =COUNTIFS('R1 Chunk Dominant'!$B$2:$B$162,"DS",'R1 Chunk Dominant'!$D$2:$D$162,"PPG") | F10: =COUNTIFS('R1 Chunk Dominant'!$B$2:$B$162,"DS",'R1 Chunk Dominant'!$D$2:$D$162,"SC") | G10: =SUM(C10:F10)
B11: Human: PPG | C11: =COUNTIFS('R1 Chunk Dominant'!$B$2:$B$162,"PPG",'R1 Chunk Dominant'!$D$2:$D$162,"PS") | D11: =COUNTIFS('R1 Chunk Dominant'!$B$2:$B$162,"PPG",'R1 Chunk Dominant'!$D$2:$D$162,"DS") | E11: =COUNTIFS('R1 Chunk Dominant'!$B$2:$B$162,"PPG",'R1 Chunk Dominant'!$D$2:$D$162,"PPG") | F11: =COUNTIFS('R1 Chunk Dominant'!$B$2:$B$162,"PPG",'R1 Chunk Dominant'!$D$2:$D$162,"SC") | G11: =SUM(C11:F11)
B12: Human: SC | C12: =COUNTIFS('R1 Chunk Dominant'!$B$2:$B$162,"SC",'R1 Chunk Dominant'!$D$2:$D$162,"PS") | D12: =COUNTIFS('R1 Chunk Dominant'!$B$2:$B$162,"SC",'R1 Chunk Dominant'!$D$2:$D$162,"DS") | E12: =COUNTIFS('R1 Chunk Dominant'!$B$2:$B$162,"SC",'R1 Chunk Dominant'!$D$2:$D$162,"PPG") | F12: =COUNTIFS('R1 Chunk Dominant'!$B$2:$B$162,"SC",'R1 Chunk Dominant'!$D$2:$D$162,"SC") | G12: =SUM(C12:F12)
B13: Col total | C13: =SUM(C9:C12) | D13: =SUM(D9:D12) | E13: =SUM(E9:E12) | F13: =SUM(F9:F12) | G13: =SUM(G9:G12)
B15: Expected under independence
C16: =$G9*C$13/$G$13 | D16: =$G9*D$13/$G$13 | E16: =$G9*E$13/$G$13 | F16: =$G9*F$13/$G$13
C17: =$G10*C$13/$G$13 | D17: =$G10*D$13/$G$13 | E17: =$G10*E$13/$G$13 | F17: =$G10*F$13/$G$13
C18: =$G11*C$13/$G$13 | D18: =$G11*D$13/$G$13 | E18: =$G11*E$13/$G$13 | F18: =$G11*F$13/$G$13
C19: =$G12*C$13/$G$13 | D19: =$G12*D$13/$G$13 | E19: =$G12*E$13/$G$13 | F19: =$G12*F$13/$G$13
B21: Raw agreement (% chunks, matching dominant logic) | G21: =(C9+D10+E11+F12)/G13
B22: PS/DS/PPG/SC are NOMINAL categories (no established ordering), so every off-diagonal mismatch is weighted equally.
B23: PRIMARY — standard (nominal, unweighted) Cohen’s kappa
C24: 0 | D24: 1 | E24: 1 | F24: 1
C25: 1 | D25: 0 | E25: 1 | F25: 1
C26: 1 | D26: 1 | E26: 0 | F26: 1
C27: 1 | D27: 1 | E27: 1 | F27: 0
B29: Kappa | G29: =1-SUMPRODUCT(C24:F27,C9:F12)/SUMPRODUCT(C24:F27,C16:F19)
B32: RETIRED — quadratic ordinal weights (i−j)² — assumed PS<DS<PPG<SC, no theoretical basis; kept only for comparison to the earlier version of this analysis
C33: 0 | D33: 1 | E33: 4 | F33: 9
C34: 1 | D34: 0 | E34: 1 | F34: 4
C35: 4 | D35: 1 | E35: 0 | F35: 1
C36: 9 | D36: 4 | E36: 1 | F36: 0
B38: Kappa | G38: =1-SUMPRODUCT(C33:F36,C9:F12)/SUMPRODUCT(C33:F36,C16:F19)
B41: RETIRED — linear ordinal weights |i−j| — same caveat as above
C42: 0 | D42: 1 | E42: 2 | F42: 3
C43: 1 | D43: 0 | E43: 1 | F43: 2
C44: 2 | D44: 1 | E44: 0 | F44: 1
C45: 3 | D45: 2 | E45: 1 | F45: 0
B47: Kappa | G47: =1-SUMPRODUCT(C42:F45,C9:F12)/SUMPRODUCT(C42:F45,C16:F19)
B50: B. Sensitivity — ties excluded
C51: AI: PS | D51: AI: DS | E51: AI: PPG | F51: AI: SC | G51: Row total
B52: Human: PS | C52: =COUNTIFS('R1 Chunk Dominant'!$B$2:$B$162,"PS",'R1 Chunk Dominant'!$D$2:$D$162,"PS",'R1 Chunk Dominant'!$C$2:$C$162,FALSE,'R1 Chunk Dominant'!$E$2:$E$162,FALSE) | D52: =COUNTIFS('R1 Chunk Dominant'!$B$2:$B$162,"PS",'R1 Chunk Dominant'!$D$2:$D$162,"DS",'R1 Chunk Dominant'!$C$2:$C$162,FALSE,'R1 Chunk Dominant'!$E$2:$E$162,FALSE) | E52: =COUNTIFS('R1 Chunk Dominant'!$B$2:$B$162,"PS",'R1 Chunk Dominant'!$D$2:$D$162,"PPG",'R1 Chunk Dominant'!$C$2:$C$162,FALSE,'R1 Chunk Dominant'!$E$2:$E$162,FALSE) | F52: =COUNTIFS('R1 Chunk Dominant'!$B$2:$B$162,"PS",'R1 Chunk Dominant'!$D$2:$D$162,"SC",'R1 Chunk Dominant'!$C$2:$C$162,FALSE,'R1 Chunk Dominant'!$E$2:$E$162,FALSE) | G52: =SUM(C52:F52)
B53: Human: DS | C53: =COUNTIFS('R1 Chunk Dominant'!$B$2:$B$162,"DS",'R1 Chunk Dominant'!$D$2:$D$162,"PS",'R1 Chunk Dominant'!$C$2:$C$162,FALSE,'R1 Chunk Dominant'!$E$2:$E$162,FALSE) | D53: =COUNTIFS('R1 Chunk Dominant'!$B$2:$B$162,"DS",'R1 Chunk Dominant'!$D$2:$D$162,"DS",'R1 Chunk Dominant'!$C$2:$C$162,FALSE,'R1 Chunk Dominant'!$E$2:$E$162,FALSE) | E53: =COUNTIFS('R1 Chunk Dominant'!$B$2:$B$162,"DS",'R1 Chunk Dominant'!$D$2:$D$162,"PPG",'R1 Chunk Dominant'!$C$2:$C$162,FALSE,'R1 Chunk Dominant'!$E$2:$E$162,FALSE) | F53: =COUNTIFS('R1 Chunk Dominant'!$B$2:$B$162,"DS",'R1 Chunk Dominant'!$D$2:$D$162,"SC",'R1 Chunk Dominant'!$C$2:$C$162,FALSE,'R1 Chunk Dominant'!$E$2:$E$162,FALSE) | G53: =SUM(C53:F53)
B54: Human: PPG | C54: =COUNTIFS('R1 Chunk Dominant'!$B$2:$B$162,"PPG",'R1 Chunk Dominant'!$D$2:$D$162,"PS",'R1 Chunk Dominant'!$C$2:$C$162,FALSE,'R1 Chunk Dominant'!$E$2:$E$162,FALSE) | D54: =COUNTIFS('R1 Chunk Dominant'!$B$2:$B$162,"PPG",'R1 Chunk Dominant'!$D$2:$D$162,"DS",'R1 Chunk Dominant'!$C$2:$C$162,FALSE,'R1 Chunk Dominant'!$E$2:$E$162,FALSE) | E54: =COUNTIFS('R1 Chunk Dominant'!$B$2:$B$162,"PPG",'R1 Chunk Dominant'!$D$2:$D$162,"PPG",'R1 Chunk Dominant'!$C$2:$C$162,FALSE,'R1 Chunk Dominant'!$E$2:$E$162,FALSE) | F54: =COUNTIFS('R1 Chunk Dominant'!$B$2:$B$162,"PPG",'R1 Chunk Dominant'!$D$2:$D$162,"SC",'R1 Chunk Dominant'!$C$2:$C$162,FALSE,'R1 Chunk Dominant'!$E$2:$E$162,FALSE) | G54: =SUM(C54:F54)
B55: Human: SC | C55: =COUNTIFS('R1 Chunk Dominant'!$B$2:$B$162,"SC",'R1 Chunk Dominant'!$D$2:$D$162,"PS",'R1 Chunk Dominant'!$C$2:$C$162,FALSE,'R1 Chunk Dominant'!$E$2:$E$162,FALSE) | D55: =COUNTIFS('R1 Chunk Dominant'!$B$2:$B$162,"SC",'R1 Chunk Dominant'!$D$2:$D$162,"DS",'R1 Chunk Dominant'!$C$2:$C$162,FALSE,'R1 Chunk Dominant'!$E$2:$E$162,FALSE) | E55: =COUNTIFS('R1 Chunk Dominant'!$B$2:$B$162,"SC",'R1 Chunk Dominant'!$D$2:$D$162,"PPG",'R1 Chunk Dominant'!$C$2:$C$162,FALSE,'R1 Chunk Dominant'!$E$2:$E$162,FALSE) | F55: =COUNTIFS('R1 Chunk Dominant'!$B$2:$B$162,"SC",'R1 Chunk Dominant'!$D$2:$D$162,"SC",'R1 Chunk Dominant'!$C$2:$C$162,FALSE,'R1 Chunk Dominant'!$E$2:$E$162,FALSE) | G55: =SUM(C55:F55)
...

Sheet R2 Chunk-level
A1: Chunk ID | B1: Text | C1: Human # applic. | D1: AI # applic. | E1: Human # incompl. | F1: AI # incompl. | G1: Coded by both? | H1: Human pts PS | I1: Human pts DS | J1: Human pts PPG | K1: Human pts SC | L1: AI pts PS | M1: AI pts DS | N1: AI pts PPG | O1: AI pts SC | P1: Human % PS | Q1: Human % DS | R1: Human % PPG | S1: Human % SC | T1: AI % PS | U1: AI % DS | V1: AI % PPG | W1: AI % SC
A2: 2 | B2: 2022 Annual Report | C2: 0 | D2: 0 | E2: 0 | F2: 0 | G2: FALSE | H2: 0 | I2: 0 | J2: 0 | K2: 0 | L2: 0 | M2: 0 | N2: 0 | O2: 0 | P2: =IF(SUM(H2:K2)=0,"",H2/SUM(H2:K2)) | Q2: =IF(SUM(H2:K2)=0,"",I2/SUM(H2:K2)) | R2: =IF(SUM(H2:K2)=0,"",J2/SUM(H2:K2)) | S2: =IF(SUM(H2:K2)=0,"",K2/SUM(H2:K2)) | T2: =IF(SUM(L2:O2)=0,"",L2/SUM(L2:O2)) | U2: =IF(SUM(L2:O2)=0,"",M2/SUM(L2:O2)) | V2: =IF(SUM(L2:O2)=0,"",N2/SUM(L2:O2)) | W2: =IF(SUM(L2:O2)=0,"",O2/SUM(L2:O2))
A3: 3 | B3: [community_foundation_tag] Purpose Statement [community_foundation_tag] exist to cultivate the power of giving within [community_foundation_tag] community, support long-term transformation, and help ensure all residents thrive. | C3: 1 | D3: 3 | E3: 0 | F3: 0 | G3: TRUE | H3: 2 | I3: 0 | J3: 1 | K3: 0 | L3: 2 | M3: 0 | N3: 4 | O3: 3 | P3: =IF(SUM(H3:K3)=0,"",H3/SUM(H3:K3)) | Q3: =IF(SUM(H3:K3)=0,"",I3/SUM(H3:K3)) | R3: =IF(SUM(H3:K3)=0,"",J3/SUM(H3:K3)) | S3: =IF(SUM(H3:K3)=0,"",K3/SUM(H3:K3)) | T3: =IF(SUM(L3:O3)=0,"",L3/SUM(L3:O3)) | U3: =IF(SUM(L3:O3)=0,"",M3/SUM(L3:O3)) | V3: =IF(SUM(L3:O3)=0,"",N3/SUM(L3:O3)) | W3: =IF(SUM(L3:O3)=0,"",O3/SUM(L3:O3))
A4: 7 | B4: Welcome to [community_foundation_tag], your local leader in community philanthropy since 1973. | C4: 1 | D4: 2 | E4: 0 | F4: 0 | G4: TRUE | H4: 0 | I4: 0 | J4: 2 | K4: 0 | L4: 4 | M4: 0 | N4: 2 | O4: 0 | P4: =IF(SUM(H4:K4)=0,"",H4/SUM(H4:K4)) | Q4: =IF(SUM(H4:K4)=0,"",I4/SUM(H4:K4)) | R4: =IF(SUM(H4:K4)=0,"",J4/SUM(H4:K4)) | S4: =IF(SUM(H4:K4)=0,"",K4/SUM(H4:K4)) | T4: =IF(SUM(L4:O4)=0,"",L4/SUM(L4:O4)) | U4: =IF(SUM(L4:O4)=0,"",M4/SUM(L4:O4)) | V4: =IF(SUM(L4:O4)=0,"",N4/SUM(L4:O4)) | W4: =IF(SUM(L4:O4)=0,"",O4/SUM(L4:O4))
A5: 8 | B5: [community_foundation_tag] believe anyone can be a philanthropist, facilitating a broad scope of avenues for involvement and bringing to life the philanthropic goals of foundation members. | C5: 1 | D5: 2 | E5: 0 | F5: 0 | G5: TRUE | H5: 0 | I5: 2 | J5: 0 | K5: 0 | L5: 2 | M5: 4 | N5: 0 | O5: 0 | P5: =IF(SUM(H5:K5)=0,"",H5/SUM(H5:K5)) | Q5: =IF(SUM(H5:K5)=0,"",I5/SUM(H5:K5)) | R5: =IF(SUM(H5:K5)=0,"",J5/SUM(H5:K5)) | S5: =IF(SUM(H5:K5)=0,"",K5/SUM(H5:K5)) | T5: =IF(SUM(L5:O5)=0,"",L5/SUM(L5:O5)) | U5: =IF(SUM(L5:O5)=0,"",M5/SUM(L5:O5)) | V5: =IF(SUM(L5:O5)=0,"",N5/SUM(L5:O5)) | W5: =IF(SUM(L5:O5)=0,"",O5/SUM(L5:O5))
A6: 9 | B6: [community_foundation_tag] reflect [community_foundation_tag] donors' and community partners' broad array of interests, including arts, culture, economic development, education, environment, health, human services, neighboring, and recreation. [community_foundation_tag] supports philanthropy in many ways. | C6: 1 | D6: 2 | E6: 0 | F6: 0 | G6: TRUE | H6: 0 | I6: 2 | J6: 1 | K6: 0 | L6: 0 | M6: 4 | N6: 2 | O6: 0 | P6: =IF(SUM(H6:K6)=0,"",H6/SUM(H6:K6)) | Q6: =IF(SUM(H6:K6)=0,"",I6/SUM(H6:K6)) | R6: =IF(SUM(H6:K6)=0,"",J6/SUM(H6:K6)) | S6: =IF(SUM(H6:K6)=0,"",K6/SUM(H6:K6)) | T6: =IF(SUM(L6:O6)=0,"",L6/SUM(L6:O6)) | U6: =IF(SUM(L6:O6)=0,"",M6/SUM(L6:O6)) | V6: =IF(SUM(L6:O6)=0,"",N6/SUM(L6:O6)) | W6: =IF(SUM(L6:O6)=0,"",O6/SUM(L6:O6))
A7: 10 | B7: A few examples are: | C7: 0 | D7: 0 | E7: 0 | F7: 0 | G7: FALSE | H7: 0 | I7: 0 | J7: 0 | K7: 0 | L7: 0 | M7: 0 | N7: 0 | O7: 0 | P7: =IF(SUM(H7:K7)=0,"",H7/SUM(H7:K7)) | Q7: =IF(SUM(H7:K7)=0,"",I7/SUM(H7:K7)) | R7: =IF(SUM(H7:K7)=0,"",J7/SUM(H7:K7)) | S7: =IF(SUM(H7:K7)=0,"",K7/SUM(H7:K7)) | T7: =IF(SUM(L7:O7)=0,"",L7/SUM(L7:O7)) | U7: =IF(SUM(L7:O7)=0,"",M7/SUM(L7:O7)) | V7: =IF(SUM(L7:O7)=0,"",N7/SUM(L7:O7)) | W7: =IF(SUM(L7:O7)=0,"",O7/SUM(L7:O7))
A8: 11 | B8: Grants - [community_foundation_tag] goes beyond making grants that advance charitable activities. [community_foundation_tag] identifies current and emerging community gaps, helps the community prepare for the future, and provides donors the opportunity to leave lasting legacies. | C8: 1 | D8: 2 | E8: 0 | F8: 0 | G8: TRUE | H8: 2 | I8: 1 | J8: 0 | K8: 0 | L8: 2 | M8: 0 | N8: 4 | O8: 0 | P8: =IF(SUM(H8:K8)=0,"",H8/SUM(H8:K8)) | Q8: =IF(SUM(H8:K8)=0,"",I8/SUM(H8:K8)) | R8: =IF(SUM(H8:K8)=0,"",J8/SUM(H8:K8)) | S8: =IF(SUM(H8:K8)=0,"",K8/SUM(H8:K8)) | T8: =IF(SUM(L8:O8)=0,"",L8/SUM(L8:O8)) | U8: =IF(SUM(L8:O8)=0,"",M8/SUM(L8:O8)) | V8: =IF(SUM(L8:O8)=0,"",N8/SUM(L8:O8)) | W8: =IF(SUM(L8:O8)=0,"",O8/SUM(L8:O8))
A9: 12 | B9: [community_foundation_tag] granted over $12 million in 2022 to support a wide array of community programming and nonprofits. | C9: 0 | D9: 2 | E9: 0 | F9: 0 | G9: FALSE | H9: 0 | I9: 0 | J9: 0 | K9: 0 | L9: 4 | M9: 0 | N9: 2 | O9: 0 | P9: =IF(SUM(H9:K9)=0,"",H9/SUM(H9:K9)) | Q9: =IF(SUM(H9:K9)=0,"",I9/SUM(H9:K9)) | R9: =IF(SUM(H9:K9)=0,"",J9/SUM(H9:K9)) | S9: =IF(SUM(H9:K9)=0,"",K9/SUM(H9:K9)) | T9: =IF(SUM(L9:O9)=0,"",L9/SUM(L9:O9)) | U9: =IF(SUM(L9:O9)=0,"",M9/SUM(L9:O9)) | V9: =IF(SUM(L9:O9)=0,"",N9/SUM(L9:O9)) | W9: =IF(SUM(L9:O9)=0,"",O9/SUM(L9:O9))
A10: 13 | B10: Scholarships - [community_foundation_tag] commits to providing students the opportunity to continue their education beyond high school. Scholarships provide an investment in the community's future, developing talent by helping students achieve their dreams. | C10: 1 | D10: 2 | E10: 0 | F10: 0 | G10: TRUE | H10: 0 | I10: 0 | J10: 2 | K10: 0 | L10: 1 | M10: 2 | N10: 3 | O10: 0 | P10: =IF(SUM(H10:K10)=0,"",H10/SUM(H10:K10)) | Q10: =IF(SUM(H10:K10)=0,"",I10/SUM(H10:K10)) | R10: =IF(SUM(H10:K10)=0,"",J10/SUM(H10:K10)) | S10: =IF(SUM(H10:K10)=0,"",K10/SUM(H10:K10)) | T10: =IF(SUM(L10:O10)=0,"",L10/SUM(L10:O10)) | U10: =IF(SUM(L10:O10)=0,"",M10/SUM(L10:O10)) | V10: =IF(SUM(L10:O10)=0,"",N10/SUM(L10:O10)) | W10: =IF(SUM(L10:O10)=0,"",O10/SUM(L10:O10))
A11: 14 | B11: For example, the Midland Believes Scholarship, since 2017, has provided over $125,000 to first-generation college students to pursue postsecondary certificates and college degrees. | C11: 1 | D11: 2 | E11: 0 | F11: 0 | G11: TRUE | H11: 0 | I11: 0 | J11: 1 | K11: 2 | L11: 0 | M11: 2 | N11: 0 | O11: 4 | P11: =IF(SUM(H11:K11)=0,"",H11/SUM(H11:K11)) | Q11: =IF(SUM(H11:K11)=0,"",I11/SUM(H11:K11)) | R11: =IF(SUM(H11:K11)=0,"",J11/SUM(H11:K11)) | S11: =IF(SUM(H11:K11)=0,"",K11/SUM(H11:K11)) | T11: =IF(SUM(L11:O11)=0,"",L11/SUM(L11:O11)) | U11: =IF(SUM(L11:O11)=0,"",M11/SUM(L11:O11)) | V11: =IF(SUM(L11:O11)=0,"",N11/SUM(L11:O11)) | W11: =IF(SUM(L11:O11)=0,"",O11/SUM(L11:O11))
A12: 15 | B12: Projects - Project funds permit [community_foundation_tag] members to donate for specific purposes. They provide an opportunity for [community_foundation_tag] to offer service and leadership to the community. | C12: 1 | D12: 2 | E12: 0 | F12: 0 | G12: TRUE | H12: 0 | I12: 2 | J12: 1 | K12: 0 | L12: 1 | M12: 4 | N12: 1 | O12: 0 | P12: =IF(SUM(H12:K12)=0,"",H12/SUM(H12:K12)) | Q12: =IF(SUM(H12:K12)=0,"",I12/SUM(H12:K12)) | R12: =IF(SUM(H12:K12)=0,"",J12/SUM(H12:K12)) | S12: =IF(SUM(H12:K12)=0,"",K12/SUM(H12:K12)) | T12: =IF(SUM(L12:O12)=0,"",L12/SUM(L12:O12)) | U12: =IF(SUM(L12:O12)=0,"",M12/SUM(L12:O12)) | V12: =IF(SUM(L12:O12)=0,"",N12/SUM(L12:O12)) | W12: =IF(SUM(L12:O12)=0,"",O12/SUM(L12:O12))
A13: 16 | B13: These funds vary in size and scope. | C13: 0 | D13: 1 | E13: 0 | F13: 0 | G13: FALSE | H13: 0 | I13: 0 | J13: 0 | K13: 0 | L13: 1 | M13: 2 | N13: 0 | O13: 0 | P13: =IF(SUM(H13:K13)=0,"",H13/SUM(H13:K13)) | Q13: =IF(SUM(H13:K13)=0,"",I13/SUM(H13:K13)) | R13: =IF(SUM(H13:K13)=0,"",J13/SUM(H13:K13)) | S13: =IF(SUM(H13:K13)=0,"",K13/SUM(H13:K13)) | T13: =IF(SUM(L13:O13)=0,"",L13/SUM(L13:O13)) | U13: =IF(SUM(L13:O13)=0,"",M13/SUM(L13:O13)) | V13: =IF(SUM(L13:O13)=0,"",N13/SUM(L13:O13)) | W13: =IF(SUM(L13:O13)=0,"",O13/SUM(L13:O13))
... A334: 392 | B334: 76 Ashman Circle | Midland, MI 48640 | 989.839.9661 | C334: 0 | D334: 0 | E334: 0 | F334: 0 | G334: FALSE | H334: 0 | I334: 0 | J334: 0 | K334: 0 | L334: 0 | M334: 0 | N334: 0 | O334: 0 | P334: =IF(SUM(H334:K334)=0,"",H334/SUM(H334:K334)) | Q334: =IF(SUM(H334:K334)=0,"",I334/SUM(H334:K334)) | R334: =IF(SUM(H334:K334)=0,"",J334/SUM(H334:K334)) | S334: =IF(SUM(H334:K334)=0,"",K334/SUM(H334:K334)) | T334: =IF(SUM(L334:O334)=0,"",L334/SUM(L334:O334)) | U334: =IF(SUM(L334:O334)=0,"",M334/SUM(L334:O334)) | V334: =IF(SUM(L334:O334)=0,"",N334/SUM(L334:O334)) | W334: =IF(SUM(L334:O334)=0,"",O334/SUM(L334:O334))

Sheet R2 Doc Aggregate
B2: Document-level totals — 382023395_2022
B4: Logic | C4: Human points | D4: Human % | E4: AI points | F4: AI %
B5: PS — Philanthropic Stewardship | C5: =SUMIFS('R2 Chunk-level'!H2:H334,'R2 Chunk-level'!G2:G334,TRUE) | D5: =IF($C$9=0,"",C5/$C$9) | E5: =SUMIFS('R2 Chunk-level'!L2:L334,'R2 Chunk-level'!G2:G334,TRUE) | F5: =IF($E$9=0,"",E5/$E$9)
B6: DS — Donor Services | C6: =SUMIFS('R2 Chunk-level'!I2:I334,'R2 Chunk-level'!G2:G334,TRUE) | D6: =IF($C$9=0,"",C6/$C$9) | E6: =SUMIFS('R2 Chunk-level'!M2:M334,'R2 Chunk-level'!G2:G334,TRUE) | F6: =IF($E$9=0,"",E6/$E$9)
B7: PPG — Public-Private Governance | C7: =SUMIFS('R2 Chunk-level'!J2:J334,'R2 Chunk-level'!G2:G334,TRUE) | D7: =IF($C$9=0,"",C7/$C$9) | E7: =SUMIFS('R2 Chunk-level'!N2:N334,'R2 Chunk-level'!G2:G334,TRUE) | F7: =IF($E$9=0,"",E7/$E$9)
B8: SC — Social Change | C8: =SUMIFS('R2 Chunk-level'!K2:K334,'R2 Chunk-level'!G2:G334,TRUE) | D8: =IF($C$9=0,"",C8/$C$9) | E8: =SUMIFS('R2 Chunk-level'!O2:O334,'R2 Chunk-level'!G2:G334,TRUE) | F8: =IF($E$9=0,"",E8/$E$9)
B9: Total | C9: =SUM(C5:C8) | E9: =SUM(E5:E8)

Sheet R2 Chunk Dominant
A1: Chunk ID | B1: Human dominant | C1: Human tie? | D1: AI dominant | E1: AI tie? | F1: Match?
A2: 3 | B2: PS | C2: FALSE | D2: PPG | E2: FALSE | F2: FALSE
A3: 7 | B3: PPG | C3: FALSE | D3: PS | E3: FALSE | F3: FALSE
A4: 8 | B4: DS | C4: FALSE | D4: DS | E4: FALSE | F4: TRUE
A5: 9 | B5: DS | C5: FALSE | D5: DS | E5: FALSE | F5: TRUE
A6: 11 | B6: PS | C6: FALSE | D6: PPG | E6: FALSE | F6: FALSE
A7: 13 | B7: PPG | C7: FALSE | D7: PPG | E7: FALSE | F7: TRUE
A8: 14 | B8: SC | C8: FALSE | D8: SC | E8: FALSE | F8: TRUE
A9: 15 | B9: DS | C9: FALSE | D9: DS | E9: FALSE | F9: TRUE
A10: 17 | B10: PPG | C10: FALSE | D10: PS | E10: FALSE | F10: FALSE
A11: 18 | B11: DS | C11: FALSE | D11: DS | E11: FALSE | F11: TRUE
A12: 19 | B12: PS | C12: TRUE | D12: DS | E12: FALSE | F12: FALSE
A13: 20 | B13: PPG | C13: FALSE | D13: PS | E13: FALSE | F13: FALSE
... A114: 334 | B114: PS | C114: FALSE | D114: PS | E114: TRUE | F114: TRUE

Sheet R2 Agreement
B2: Chunk-level agreement — 382023395_2022
B3: N=113 chunks coded by both coders. Ties: 2 human, 3 AI (broken PS>DS>PPG>SC).
B7: A. Full sample
C8: AI: PS | D8: AI: DS | E8: AI: PPG | F8: AI: SC | G8: Row total
B9: Human: PS | C9: =COUNTIFS('R2 Chunk Dominant'!$B$2:$B$114,"PS",'R2 Chunk Dominant'!$D$2:$D$114,"PS") | D9: =COUNTIFS('R2 Chunk Dominant'!$B$2:$B$114,"PS",'R2 Chunk Dominant'!$D$2:$D$114,"DS") | E9: =COUNTIFS('R2 Chunk Dominant'!$B$2:$B$114,"PS",'R2 Chunk Dominant'!$D$2:$D$114,"PPG") | F9: =COUNTIFS('R2 Chunk Dominant'!$B$2:$B$114,"PS",'R2 Chunk Dominant'!$D$2:$D$114,"SC") | G9: =SUM(C9:F9)
B10: Human: DS | C10: =COUNTIFS('R2 Chunk Dominant'!$B$2:$B$114,"DS",'R2 Chunk Dominant'!$D$2:$D$114,"PS") | D10: =COUNTIFS('R2 Chunk Dominant'!$B$2:$B$114,"DS",'R2 Chunk Dominant'!$D$2:$D$114,"DS") | E10: =COUNTIFS('R2 Chunk Dominant'!$B$2:$B$114,"DS",'R2 Chunk Dominant'!$D$2:$D$114,"PPG") | F10: =COUNTIFS('R2 Chunk Dominant'!$B$2:$B$114,"DS",'R2 Chunk Dominant'!$D$2:$D$114,"SC") | G10: =SUM(C10:F10)
B11: Human: PPG | C11: =COUNTIFS('R2 Chunk Dominant'!$B$2:$B$114,"PPG",'R2 Chunk Dominant'!$D$2:$D$114,"PS") | D11: =COUNTIFS('R2 Chunk Dominant'!$B$2:$B$114,"PPG",'R2 Chunk Dominant'!$D$2:$D$114,"DS") | E11: =COUNTIFS('R2 Chunk Dominant'!$B$2:$B$114,"PPG",'R2 Chunk Dominant'!$D$2:$D$114,"PPG") | F11: =COUNTIFS('R2 Chunk Dominant'!$B$2:$B$114,"PPG",'R2 Chunk Dominant'!$D$2:$D$114,"SC") | G11: =SUM(C11:F11)
B12: Human: SC | C12: =COUNTIFS('R2 Chunk Dominant'!$B$2:$B$114,"SC",'R2 Chunk Dominant'!$D$2:$D$114,"PS") | D12: =COUNTIFS('R2 Chunk Dominant'!$B$2:$B$114,"SC",'R2 Chunk Dominant'!$D$2:$D$114,"DS") | E12: =COUNTIFS('R2 Chunk Dominant'!$B$2:$B$114,"SC",'R2 Chunk Dominant'!$D$2:$D$114,"PPG") | F12: =COUNTIFS('R2 Chunk Dominant'!$B$2:$B$114,"SC",'R2 Chunk Dominant'!$D$2:$D$114,"SC") | G12: =SUM(C12:F12)
B13: Col total | C13: =SUM(C9:C12) | D13: =SUM(D9:D12) | E13: =SUM(E9:E12) | F13: =SUM(F9:F12) | G13: =SUM(G9:G12)
B15: Expected under independence
C16: =$G9*C$13/$G$13 | D16: =$G9*D$13/$G$13 | E16: =$G9*E$13/$G$13 | F16: =$G9*F$13/$G$13
C17: =$G10*C$13/$G$13 | D17: =$G10*D$13/$G$13 | E17: =$G10*E$13/$G$13 | F17: =$G10*F$13/$G$13
C18: =$G11*C$13/$G$13 | D18: =$G11*D$13/$G$13 | E18: =$G11*E$13/$G$13 | F18: =$G11*F$13/$G$13
C19: =$G12*C$13/$G$13 | D19: =$G12*D$13/$G$13 | E19: =$G12*E$13/$G$13 | F19: =$G12*F$13/$G$13
B21: Raw agreement (% chunks, matching dominant logic) | G21: =(C9+D10+E11+F12)/G13
B22: PS/DS/PPG/SC are NOMINAL categories (no established ordering), so every off-diagonal mismatch is weighted equally.
B23: PRIMARY — standard (nominal, unweighted) Cohen’s kappa
C24: 0 | D24: 1 | E24: 1 | F24: 1
C25: 1 | D25: 0 | E25: 1 | F25: 1
C26: 1 | D26: 1 | E26: 0 | F26: 1
C27: 1 | D27: 1 | E27: 1 | F27: 0
B29: Kappa | G29: =1-SUMPRODUCT(C24:F27,C9:F12)/SUMPRODUCT(C24:F27,C16:F19)
B32: RETIRED — quadratic ordinal weights (i−j)² — assumed PS<DS<PPG<SC, no theoretical basis; kept only for comparison to the earlier version of this analysis
C33: 0 | D33: 1 | E33: 4 | F33: 9
C34: 1 | D34: 0 | E34: 1 | F34: 4
C35: 4 | D35: 1 | E35: 0 | F35: 1
C36: 9 | D36: 4 | E36: 1 | F36: 0
B38: Kappa | G38: =1-SUMPRODUCT(C33:F36,C9:F12)/SUMPRODUCT(C33:F36,C16:F19)
B41: RETIRED — linear ordinal weights |i−j| — same caveat as above
C42: 0 | D42: 1 | E42: 2 | F42: 3
C43: 1 | D43: 0 | E43: 1 | F43: 2
C44: 2 | D44: 1 | E44: 0 | F44: 1
C45: 3 | D45: 2 | E45: 1 | F45: 0
B47: Kappa | G47: =1-SUMPRODUCT(C42:F45,C9:F12)/SUMPRODUCT(C42:F45,C16:F19)
B50: B. Sensitivity — ties excluded
C51: AI: PS | D51: AI: DS | E51: AI: PPG | F51: AI: SC | G51: Row total
B52: Human: PS | C52: =COUNTIFS('R2 Chunk Dominant'!$B$2:$B$114,"PS",'R2 Chunk Dominant'!$D$2:$D$114,"PS",'R2 Chunk Dominant'!$C$2:$C$114,FALSE,'R2 Chunk Dominant'!$E$2:$E$114,FALSE) | D52: =COUNTIFS('R2 Chunk Dominant'!$B$2:$B$114,"PS",'R2 Chunk Dominant'!$D$2:$D$114,"DS",'R2 Chunk Dominant'!$C$2:$C$114,FALSE,'R2 Chunk Dominant'!$E$2:$E$114,FALSE) | E52: =COUNTIFS('R2 Chunk Dominant'!$B$2:$B$114,"PS",'R2 Chunk Dominant'!$D$2:$D$114,"PPG",'R2 Chunk Dominant'!$C$2:$C$114,FALSE,'R2 Chunk Dominant'!$E$2:$E$114,FALSE) | F52: =COUNTIFS('R2 Chunk Dominant'!$B$2:$B$114,"PS",'R2 Chunk Dominant'!$D$2:$D$114,"SC",'R2 Chunk Dominant'!$C$2:$C$114,FALSE,'R2 Chunk Dominant'!$E$2:$E$114,FALSE) | G52: =SUM(C52:F52)
B53: Human: DS | C53: =COUNTIFS('R2 Chunk Dominant'!$B$2:$B$114,"DS",'R2 Chunk Dominant'!$D$2:$D$114,"PS",'R2 Chunk Dominant'!$C$2:$C$114,FALSE,'R2 Chunk Dominant'!$E$2:$E$114,FALSE) | D53: =COUNTIFS('R2 Chunk Dominant'!$B$2:$B$114,"DS",'R2 Chunk Dominant'!$D$2:$D$114,"DS",'R2 Chunk Dominant'!$C$2:$C$114,FALSE,'R2 Chunk Dominant'!$E$2:$E$114,FALSE) | E53: =COUNTIFS('R2 Chunk Dominant'!$B$2:$B$114,"DS",'R2 Chunk Dominant'!$D$2:$D$114,"PPG",'R2 Chunk Dominant'!$C$2:$C$114,FALSE,'R2 Chunk Dominant'!$E$2:$E$114,FALSE) | F53: =COUNTIFS('R2 Chunk Dominant'!$B$2:$B$114,"DS",'R2 Chunk Dominant'!$D$2:$D$114,"SC",'R2 Chunk Dominant'!$C$2:$C$114,FALSE,'R2 Chunk Dominant'!$E$2:$E$114,FALSE) | G53: =SUM(C53:F53)
B54: Human: PPG | C54: =COUNTIFS('R2 Chunk Dominant'!$B$2:$B$114,"PPG",'R2 Chunk Dominant'!$D$2:$D$114,"PS",'R2 Chunk Dominant'!$C$2:$C$114,FALSE,'R2 Chunk Dominant'!$E$2:$E$114,FALSE) | D54: =COUNTIFS('R2 Chunk Dominant'!$B$2:$B$114,"PPG",'R2 Chunk Dominant'!$D$2:$D$114,"DS",'R2 Chunk Dominant'!$C$2:$C$114,FALSE,'R2 Chunk Dominant'!$E$2:$E$114,FALSE) | E54: =COUNTIFS('R2 Chunk Dominant'!$B$2:$B$114,"PPG",'R2 Chunk Dominant'!$D$2:$D$114,"PPG",'R2 Chunk Dominant'!$C$2:$C$114,FALSE,'R2 Chunk Dominant'!$E$2:$E$114,FALSE) | F54: =COUNTIFS('R2 Chunk Dominant'!$B$2:$B$114,"PPG",'R2 Chunk Dominant'!$D$2:$D$114,"SC",'R2 Chunk Dominant'!$C$2:$C$114,FALSE,'R2 Chunk Dominant'!$E$2:$E$114,FALSE) | G54: =SUM(C54:F54)
B55: Human: SC | C55: =COUNTIFS('R2 Chunk Dominant'!$B$2:$B$114,"SC",'R2 Chunk Dominant'!$D$2:$D$114,"PS",'R2 Chunk Dominant'!$C$2:$C$114,FALSE,'R2 Chunk Dominant'!$E$2:$E$114,FALSE) | D55: =COUNTIFS('R2 Chunk Dominant'!$B$2:$B$114,"SC",'R2 Chunk Dominant'!$D$2:$D$114,"DS",'R2 Chunk Dominant'!$C$2:$C$114,FALSE,'R2 Chunk Dominant'!$E$2:$E$114,FALSE) | E55: =COUNTIFS('R2 Chunk Dominant'!$B$2:$B$114,"SC",'R2 Chunk Dominant'!$D$2:$D$114,"PPG",'R2 Chunk Dominant'!$C$2:$C$114,FALSE,'R2 Chunk Dominant'!$E$2:$E$114,FALSE) | F55: =COUNTIFS('R2 Chunk Dominant'!$B$2:$B$114,"SC",'R2 Chunk Dominant'!$D$2:$D$114,"SC",'R2 Chunk Dominant'!$C$2:$C$114,FALSE,'R2 Chunk Dominant'!$E$2:$E$114,FALSE) | G55: =SUM(C55:F55)
...

Sheet R3 Chunk-level
A1: Chunk ID | B1: Text | C1: Human # applic. | D1: AI # applic. | E1: Human # incompl. | F1: AI # incompl. | G1: Coded by both? | H1: Human pts PS | I1: Human pts DS | J1: Human pts PPG | K1: Human pts SC | L1: AI pts PS | M1: AI pts DS | N1: AI pts PPG | O1: AI pts SC | P1: Human % PS | Q1: Human % DS | R1: Human % PPG | S1: Human % SC | T1: AI % PS | U1: AI % DS | V1: AI % PPG | W1: AI % SC
A2: 1 | B2: In 2021, [community_foundation_tag] saw a record number of new funds, scholarships and charitable gift annuities established including: | C2: 1 | D2: 2 | E2: 0 | F2: 0 | G2: TRUE | H2: 2 | I2: 0 | J2: 0 | K2: 0 | L2: 2 | M2: 4 | N2: 0 | O2: 0 | P2: =IF(SUM(H2:K2)=0,"",H2/SUM(H2:K2)) | Q2: =IF(SUM(H2:K2)=0,"",I2/SUM(H2:K2)) | R2: =IF(SUM(H2:K2)=0,"",J2/SUM(H2:K2)) | S2: =IF(SUM(H2:K2)=0,"",K2/SUM(H2:K2)) | T2: =IF(SUM(L2:O2)=0,"",L2/SUM(L2:O2)) | U2: =IF(SUM(L2:O2)=0,"",M2/SUM(L2:O2)) | V2: =IF(SUM(L2:O2)=0,"",N2/SUM(L2:O2)) | W2: =IF(SUM(L2:O2)=0,"",O2/SUM(L2:O2))
A3: 2 | B3: The Clare Wilson Honorary Fund | C3: 0 | D3: 1 | E3: 0 | F3: 0 | G3: FALSE | H3: 0 | I3: 0 | J3: 0 | K3: 0 | L3: 2 | M3: 1 | N3: 0 | O3: 0 | P3: =IF(SUM(H3:K3)=0,"",H3/SUM(H3:K3)) | Q3: =IF(SUM(H3:K3)=0,"",I3/SUM(H3:K3)) | R3: =IF(SUM(H3:K3)=0,"",J3/SUM(H3:K3)) | S3: =IF(SUM(H3:K3)=0,"",K3/SUM(H3:K3)) | T3: =IF(SUM(L3:O3)=0,"",L3/SUM(L3:O3)) | U3: =IF(SUM(L3:O3)=0,"",M3/SUM(L3:O3)) | V3: =IF(SUM(L3:O3)=0,"",N3/SUM(L3:O3)) | W3: =IF(SUM(L3:O3)=0,"",O3/SUM(L3:O3))
A4: 3 | B4: To honor his legacy of service, Fuller Hose Company established the Clare Wilson Fund. | C4: 1 | D4: 1 | E4: 0 | F4: 0 | G4: TRUE | H4: 0 | I4: 2 | J4: 0 | K4: 0 | L4: 2 | M4: 1 | N4: 0 | O4: 0 | P4: =IF(SUM(H4:K4)=0,"",H4/SUM(H4:K4)) | Q4: =IF(SUM(H4:K4)=0,"",I4/SUM(H4:K4)) | R4: =IF(SUM(H4:K4)=0,"",J4/SUM(H4:K4)) | S4: =IF(SUM(H4:K4)=0,"",K4/SUM(H4:K4)) | T4: =IF(SUM(L4:O4)=0,"",L4/SUM(L4:O4)) | U4: =IF(SUM(L4:O4)=0,"",M4/SUM(L4:O4)) | V4: =IF(SUM(L4:O4)=0,"",N4/SUM(L4:O4)) | W4: =IF(SUM(L4:O4)=0,"",O4/SUM(L4:O4))
A5: 4 | B5: The fund helps the fire company in two critical ways: meeting immediate equipment needs and ensuring that funds will be there in the future to support the changing needs of the community. In December 2021, thanks to the Clare Wilson Fund, the department received a much-needed new piece of equipment - an F550 multipurpose truck that will assist in brush fires and water rescues. | C5: 1 | D5: 4 | E5: 0 | F5: 0 | G5: TRUE | H5: 1 | I5: 0 | J5: 2 | K5: 0 | L5: 7 | M5: 1 | N5: 4 | O5: 0 | P5: =IF(SUM(H5:K5)=0,"",H5/SUM(H5:K5)) | Q5: =IF(SUM(H5:K5)=0,"",I5/SUM(H5:K5)) | R5: =IF(SUM(H5:K5)=0,"",J5/SUM(H5:K5)) | S5: =IF(SUM(H5:K5)=0,"",K5/SUM(H5:K5)) | T5: =IF(SUM(L5:O5)=0,"",L5/SUM(L5:O5)) | U5: =IF(SUM(L5:O5)=0,"",M5/SUM(L5:O5)) | V5: =IF(SUM(L5:O5)=0,"",N5/SUM(L5:O5)) | W5: =IF(SUM(L5:O5)=0,"",O5/SUM(L5:O5))
A6: 5 | B6: The John Manville &amp; Frieda Bodendorfer Phillips Fund | C6: 0 | D6: 1 | E6: 0 | F6: 0 | G6: FALSE | H6: 0 | I6: 0 | J6: 0 | K6: 0 | L6: 1 | M6: 2 | N6: 0 | O6: 0 | P6: =IF(SUM(H6:K6)=0,"",H6/SUM(H6:K6)) | Q6: =IF(SUM(H6:K6)=0,"",I6/SUM(H6:K6)) | R6: =IF(SUM(H6:K6)=0,"",J6/SUM(H6:K6)) | S6: =IF(SUM(H6:K6)=0,"",K6/SUM(H6:K6)) | T6: =IF(SUM(L6:O6)=0,"",L6/SUM(L6:O6)) | U6: =IF(SUM(L6:O6)=0,"",M6/SUM(L6:O6)) | V6: =IF(SUM(L6:O6)=0,"",N6/SUM(L6:O6)) | W6: =IF(SUM(L6:O6)=0,"",O6/SUM(L6:O6))
A7: 6 | B7: The fund was created by [individual_tag] and [individual_tag] to honor family members' contributions to the community. | C7: 1 | D7: 2 | E7: 0 | F7: 0 | G7: TRUE | H7: 0 | I7: 2 | J7: 0 | K7: 0 | L7: 4 | M7: 2 | N7: 0 | O7: 0 | P7: =IF(SUM(H7:K7)=0,"",H7/SUM(H7:K7)) | Q7: =IF(SUM(H7:K7)=0,"",I7/SUM(H7:K7)) | R7: =IF(SUM(H7:K7)=0,"",J7/SUM(H7:K7)) | S7: =IF(SUM(H7:K7)=0,"",K7/SUM(H7:K7)) | T7: =IF(SUM(L7:O7)=0,"",L7/SUM(L7:O7)) | U7: =IF(SUM(L7:O7)=0,"",M7/SUM(L7:O7)) | V7: =IF(SUM(L7:O7)=0,"",N7/SUM(L7:O7)) | W7: =IF(SUM(L7:O7)=0,"",O7/SUM(L7:O7))
A8: 7 | B8: Funds will be used to support qualified and deserving non-profit organizations whose activities and mission address agriculture and/or food related education, projects and needs. | C8: 1 | D8: 3 | E8: 0 | F8: 0 | G8: TRUE | H8: 0 | I8: 2 | J8: 0 | K8: 0 | L8: 3 | M8: 6 | N8: 0 | O8: 0 | P8: =IF(SUM(H8:K8)=0,"",H8/SUM(H8:K8)) | Q8: =IF(SUM(H8:K8)=0,"",I8/SUM(H8:K8)) | R8: =IF(SUM(H8:K8)=0,"",J8/SUM(H8:K8)) | S8: =IF(SUM(H8:K8)=0,"",K8/SUM(H8:K8)) | T8: =IF(SUM(L8:O8)=0,"",L8/SUM(L8:O8)) | U8: =IF(SUM(L8:O8)=0,"",M8/SUM(L8:O8)) | V8: =IF(SUM(L8:O8)=0,"",N8/SUM(L8:O8)) | W8: =IF(SUM(L8:O8)=0,"",O8/SUM(L8:O8))
A9: 8 | B9: The Miller Family Scholarship Fund | C9: 0 | D9: 1 | E9: 0 | F9: 0 | G9: FALSE | H9: 0 | I9: 0 | J9: 0 | K9: 0 | L9: 1 | M9: 2 | N9: 0 | O9: 0 | P9: =IF(SUM(H9:K9)=0,"",H9/SUM(H9:K9)) | Q9: =IF(SUM(H9:K9)=0,"",I9/SUM(H9:K9)) | R9: =IF(SUM(H9:K9)=0,"",J9/SUM(H9:K9)) | S9: =IF(SUM(H9:K9)=0,"",K9/SUM(H9:K9)) | T9: =IF(SUM(L9:O9)=0,"",L9/SUM(L9:O9)) | U9: =IF(SUM(L9:O9)=0,"",M9/SUM(L9:O9)) | V9: =IF(SUM(L9:O9)=0,"",N9/SUM(L9:O9)) | W9: =IF(SUM(L9:O9)=0,"",O9/SUM(L9:O9))
A10: 9 | B10: For decades, the late [individual_tag] and his family have provided scholarships to students in North East. | C10: 1 | D10: 2 | E10: 0 | F10: 0 | G10: TRUE | H10: 0 | I10: 2 | J10: 0 | K10: 0 | L10: 3 | M10: 3 | N10: 0 | O10: 0 | P10: =IF(SUM(H10:K10)=0,"",H10/SUM(H10:K10)) | Q10: =IF(SUM(H10:K10)=0,"",I10/SUM(H10:K10)) | R10: =IF(SUM(H10:K10)=0,"",J10/SUM(H10:K10)) | S10: =IF(SUM(H10:K10)=0,"",K10/SUM(H10:K10)) | T10: =IF(SUM(L10:O10)=0,"",L10/SUM(L10:O10)) | U10: =IF(SUM(L10:O10)=0,"",M10/SUM(L10:O10)) | V10: =IF(SUM(L10:O10)=0,"",N10/SUM(L10:O10)) | W10: =IF(SUM(L10:O10)=0,"",O10/SUM(L10:O10))
A11: 10 | B11: In 2021, they opted to continue this long-standing tradition by partnering with [community_foundation_tag]. | C11: 1 | D11: 2 | E11: 0 | F11: 0 | G11: TRUE | H11: 0 | I11: 2 | J11: 0 | K11: 0 | L11: 3 | M11: 3 | N11: 0 | O11: 0 | P11: =IF(SUM(H11:K11)=0,"",H11/SUM(H11:K11)) | Q11: =IF(SUM(H11:K11)=0,"",I11/SUM(H11:K11)) | R11: =IF(SUM(H11:K11)=0,"",J11/SUM(H11:K11)) | S11: =IF(SUM(H11:K11)=0,"",K11/SUM(H11:K11)) | T11: =IF(SUM(L11:O11)=0,"",L11/SUM(L11:O11)) | U11: =IF(SUM(L11:O11)=0,"",M11/SUM(L11:O11)) | V11: =IF(SUM(L11:O11)=0,"",N11/SUM(L11:O11)) | W11: =IF(SUM(L11:O11)=0,"",O11/SUM(L11:O11))
A12: 11 | B12: The Miller Family Scholarship is unique in that it is available to students of any age pursuing 2-year, 4-year or vocational education. | C12: 0 | D12: 3 | E12: 0 | F12: 0 | G12: FALSE | H12: 0 | I12: 0 | J12: 0 | K12: 0 | L12: 0 | M12: 6 | N12: 0 | O12: 3 | P12: =IF(SUM(H12:K12)=0,"",H12/SUM(H12:K12)) | Q12: =IF(SUM(H12:K12)=0,"",I12/SUM(H12:K12)) | R12: =IF(SUM(H12:K12)=0,"",J12/SUM(H12:K12)) | S12: =IF(SUM(H12:K12)=0,"",K12/SUM(H12:K12)) | T12: =IF(SUM(L12:O12)=0,"",L12/SUM(L12:O12)) | U12: =IF(SUM(L12:O12)=0,"",M12/SUM(L12:O12)) | V12: =IF(SUM(L12:O12)=0,"",N12/SUM(L12:O12)) | W12: =IF(SUM(L12:O12)=0,"",O12/SUM(L12:O12))
A13: 12 | B13: The Susan Valone MD Memorial Scholarship [individual_tag] was raised in North East and went on to become an infectious disease specialist in Colorado. | C13: 0 | D13: 1 | E13: 0 | F13: 0 | G13: FALSE | H13: 0 | I13: 0 | J13: 0 | K13: 0 | L13: 2 | M13: 1 | N13: 0 | O13: 0 | P13: =IF(SUM(H13:K13)=0,"",H13/SUM(H13:K13)) | Q13: =IF(SUM(H13:K13)=0,"",I13/SUM(H13:K13)) | R13: =IF(SUM(H13:K13)=0,"",J13/SUM(H13:K13)) | S13: =IF(SUM(H13:K13)=0,"",K13/SUM(H13:K13)) | T13: =IF(SUM(L13:O13)=0,"",L13/SUM(L13:O13)) | U13: =IF(SUM(L13:O13)=0,"",M13/SUM(L13:O13)) | V13: =IF(SUM(L13:O13)=0,"",N13/SUM(L13:O13)) | W13: =IF(SUM(L13:O13)=0,"",O13/SUM(L13:O13))
... A115: 159 | B115: United Neighborhood Facilities Health Care Co United Way of Erie County | C115: 0 | D115: 1 | E115: 0 | F115: 0 | G115: FALSE | H115: 0 | I115: 0 | J115: 0 | K115: 0 | L115: 2 | M115: 0 | N115: 0 | O115: 1 | P115: =IF(SUM(H115:K115)=0,"",H115/SUM(H115:K115)) | Q115: =IF(SUM(H115:K115)=0,"",I115/SUM(H115:K115)) | R115: =IF(SUM(H115:K115)=0,"",J115/SUM(H115:K115)) | S115: =IF(SUM(H115:K115)=0,"",K115/SUM(H115:K115)) | T115: =IF(SUM(L115:O115)=0,"",L115/SUM(L115:O115)) | U115: =IF(SUM(L115:O115)=0,"",M115/SUM(L115:O115)) | V115: =IF(SUM(L115:O115)=0,"",N115/SUM(L115:O115)) | W115: =IF(SUM(L115:O115)=0,"",O115/SUM(L115:O115))

Sheet R3 Doc Aggregate
B2: Document-level totals — 25-1650208_2021
B4: Logic | C4: Human points | D4: Human % | E4: AI points | F4: AI %
B5: PS — Philanthropic Stewardship | C5: =SUMIFS('R3 Chunk-level'!H2:H115,'R3 Chunk-level'!G2:G115,TRUE) | D5: =IF($C$9=0,"",C5/$C$9) | E5: =SUMIFS('R3 Chunk-level'!L2:L115,'R3 Chunk-level'!G2:G115,TRUE) | F5: =IF($E$9=0,"",E5/$E$9)
B6: DS — Donor Services | C6: =SUMIFS('R3 Chunk-level'!I2:I115,'R3 Chunk-level'!G2:G115,TRUE) | D6: =IF($C$9=0,"",C6/$C$9) | E6: =SUMIFS('R3 Chunk-level'!M2:M115,'R3 Chunk-level'!G2:G115,TRUE) | F6: =IF($E$9=0,"",E6/$E$9)
B7: PPG — Public-Private Governance | C7: =SUMIFS('R3 Chunk-level'!J2:J115,'R3 Chunk-level'!G2:G115,TRUE) | D7: =IF($C$9=0,"",C7/$C$9) | E7: =SUMIFS('R3 Chunk-level'!N2:N115,'R3 Chunk-level'!G2:G115,TRUE) | F7: =IF($E$9=0,"",E7/$E$9)
B8: SC — Social Change | C8: =SUMIFS('R3 Chunk-level'!K2:K115,'R3 Chunk-level'!G2:G115,TRUE) | D8: =IF($C$9=0,"",C8/$C$9) | E8: =SUMIFS('R3 Chunk-level'!O2:O115,'R3 Chunk-level'!G2:G115,TRUE) | F8: =IF($E$9=0,"",E8/$E$9)
B9: Total | C9: =SUM(C5:C8) | E9: =SUM(E5:E8)

Sheet R3 Chunk Dominant
A1: Chunk ID | B1: Human dominant | C1: Human tie? | D1: AI dominant | E1: AI tie? | F1: Match?
A2: 1 | B2: PS | C2: FALSE | D2: DS | E2: FALSE | F2: FALSE
A3: 3 | B3: DS | C3: FALSE | D3: PS | E3: FALSE | F3: FALSE
A4: 4 | B4: PPG | C4: FALSE | D4: PS | E4: FALSE | F4: FALSE
A5: 6 | B5: DS | C5: FALSE | D5: PS | E5: FALSE | F5: FALSE
A6: 7 | B6: DS | C6: FALSE | D6: DS | E6: FALSE | F6: TRUE
A7: 9 | B7: DS | C7: FALSE | D7: PS | E7: TRUE | F7: FALSE
A8: 10 | B8: DS | C8: FALSE | D8: PS | E8: TRUE | F8: FALSE
A9: 13 | B9: DS | C9: FALSE | D9: DS | E9: FALSE | F9: TRUE
A10: 14 | B10: DS | C10: FALSE | D10: DS | E10: FALSE | F10: TRUE
A11: 16 | B11: DS | C11: FALSE | D11: DS | E11: FALSE | F11: TRUE
A12: 17 | B12: DS | C12: FALSE | D12: DS | E12: FALSE | F12: TRUE
A13: 21 | B13: PS | C13: FALSE | D13: PS | E13: FALSE | F13: TRUE
... A33: 131 | B33: PS | C33: FALSE | D33: PS | E33: FALSE | F33: TRUE

Sheet R3 Agreement
B2: Chunk-level agreement — 25-1650208_2021
B3: N=32 chunks coded by both coders. Ties: 0 human, 4 AI (broken PS>DS>PPG>SC).
B7: A. Full sample
C8: AI: PS | D8: AI: DS | E8: AI: PPG | F8: AI: SC | G8: Row total
B9: Human: PS | C9: =COUNTIFS('R3 Chunk Dominant'!$B$2:$B$33,"PS",'R3 Chunk Dominant'!$D$2:$D$33,"PS") | D9: =COUNTIFS('R3 Chunk Dominant'!$B$2:$B$33,"PS",'R3 Chunk Dominant'!$D$2:$D$33,"DS") | E9: =COUNTIFS('R3 Chunk Dominant'!$B$2:$B$33,"PS",'R3 Chunk Dominant'!$D$2:$D$33,"PPG") | F9: =COUNTIFS('R3 Chunk Dominant'!$B$2:$B$33,"PS",'R3 Chunk Dominant'!$D$2:$D$33,"SC") | G9: =SUM(C9:F9)
B10: Human: DS | C10: =COUNTIFS('R3 Chunk Dominant'!$B$2:$B$33,"DS",'R3 Chunk Dominant'!$D$2:$D$33,"PS") | D10: =COUNTIFS('R3 Chunk Dominant'!$B$2:$B$33,"DS",'R3 Chunk Dominant'!$D$2:$D$33,"DS") | E10: =COUNTIFS('R3 Chunk Dominant'!$B$2:$B$33,"DS",'R3 Chunk Dominant'!$D$2:$D$33,"PPG") | F10: =COUNTIFS('R3 Chunk Dominant'!$B$2:$B$33,"DS",'R3 Chunk Dominant'!$D$2:$D$33,"SC") | G10: =SUM(C10:F10)
B11: Human: PPG | C11: =COUNTIFS('R3 Chunk Dominant'!$B$2:$B$33,"PPG",'R3 Chunk Dominant'!$D$2:$D$33,"PS") | D11: =COUNTIFS('R3 Chunk Dominant'!$B$2:$B$33,"PPG",'R3 Chunk Dominant'!$D$2:$D$33,"DS") | E11: =COUNTIFS('R3 Chunk Dominant'!$B$2:$B$33,"PPG",'R3 Chunk Dominant'!$D$2:$D$33,"PPG") | F11: =COUNTIFS('R3 Chunk Dominant'!$B$2:$B$33,"PPG",'R3 Chunk Dominant'!$D$2:$D$33,"SC") | G11: =SUM(C11:F11)
B12: Human: SC | C12: =COUNTIFS('R3 Chunk Dominant'!$B$2:$B$33,"SC",'R3 Chunk Dominant'!$D$2:$D$33,"PS") | D12: =COUNTIFS('R3 Chunk Dominant'!$B$2:$B$33,"SC",'R3 Chunk Dominant'!$D$2:$D$33,"DS") | E12: =COUNTIFS('R3 Chunk Dominant'!$B$2:$B$33,"SC",'R3 Chunk Dominant'!$D$2:$D$33,"PPG") | F12: =COUNTIFS('R3 Chunk Dominant'!$B$2:$B$33,"SC",'R3 Chunk Dominant'!$D$2:$D$33,"SC") | G12: =SUM(C12:F12)
B13: Col total | C13: =SUM(C9:C12) | D13: =SUM(D9:D12) | E13: =SUM(E9:E12) | F13: =SUM(F9:F12) | G13: =SUM(G9:G12)
B15: Expected under independence
C16: =$G9*C$13/$G$13 | D16: =$G9*D$13/$G$13 | E16: =$G9*E$13/$G$13 | F16: =$G9*F$13/$G$13
C17: =$G10*C$13/$G$13 | D17: =$G10*D$13/$G$13 | E17: =$G10*E$13/$G$13 | F17: =$G10*F$13/$G$13
C18: =$G11*C$13/$G$13 | D18: =$G11*D$13/$G$13 | E18: =$G11*E$13/$G$13 | F18: =$G11*F$13/$G$13
C19: =$G12*C$13/$G$13 | D19: =$G12*D$13/$G$13 | E19: =$G12*E$13/$G$13 | F19: =$G12*F$13/$G$13
B21: Raw agreement (% chunks, matching dominant logic) | G21: =(C9+D10+E11+F12)/G13
B22: PS/DS/PPG/SC are NOMINAL categories (no established ordering), so every off-diagonal mismatch is weighted equally.
B23: PRIMARY — standard (nominal, unweighted) Cohen’s kappa
C24: 0 | D24: 1 | E24: 1 | F24: 1
C25: 1 | D25: 0 | E25: 1 | F25: 1
C26: 1 | D26: 1 | E26: 0 | F26: 1
C27: 1 | D27: 1 | E27: 1 | F27: 0
B29: Kappa | G29: =1-SUMPRODUCT(C24:F27,C9:F12)/SUMPRODUCT(C24:F27,C16:F19)
B32: RETIRED — quadratic ordinal weights (i−j)² — assumed PS<DS<PPG<SC, no theoretical basis; kept only for comparison to the earlier version of this analysis
C33: 0 | D33: 1 | E33: 4 | F33: 9
C34: 1 | D34: 0 | E34: 1 | F34: 4
C35: 4 | D35: 1 | E35: 0 | F35: 1
C36: 9 | D36: 4 | E36: 1 | F36: 0
B38: Kappa | G38: =1-SUMPRODUCT(C33:F36,C9:F12)/SUMPRODUCT(C33:F36,C16:F19)
B41: RETIRED — linear ordinal weights |i−j| — same caveat as above
C42: 0 | D42: 1 | E42: 2 | F42: 3
C43: 1 | D43: 0 | E43: 1 | F43: 2
C44: 2 | D44: 1 | E44: 0 | F44: 1
C45: 3 | D45: 2 | E45: 1 | F45: 0
B47: Kappa | G47: =1-SUMPRODUCT(C42:F45,C9:F12)/SUMPRODUCT(C42:F45,C16:F19)
B50: B. Sensitivity — ties excluded
C51: AI: PS | D51: AI: DS | E51: AI: PPG | F51: AI: SC | G51: Row total
B52: Human: PS | C52: =COUNTIFS('R3 Chunk Dominant'!$B$2:$B$33,"PS",'R3 Chunk Dominant'!$D$2:$D$33,"PS",'R3 Chunk Dominant'!$C$2:$C$33,FALSE,'R3 Chunk Dominant'!$E$2:$E$33,FALSE) | D52: =COUNTIFS('R3 Chunk Dominant'!$B$2:$B$33,"PS",'R3 Chunk Dominant'!$D$2:$D$33,"DS",'R3 Chunk Dominant'!$C$2:$C$33,FALSE,'R3 Chunk Dominant'!$E$2:$E$33,FALSE) | E52: =COUNTIFS('R3 Chunk Dominant'!$B$2:$B$33,"PS",'R3 Chunk Dominant'!$D$2:$D$33,"PPG",'R3 Chunk Dominant'!$C$2:$C$33,FALSE,'R3 Chunk Dominant'!$E$2:$E$33,FALSE) | F52: =COUNTIFS('R3 Chunk Dominant'!$B$2:$B$33,"PS",'R3 Chunk Dominant'!$D$2:$D$33,"SC",'R3 Chunk Dominant'!$C$2:$C$33,FALSE,'R3 Chunk Dominant'!$E$2:$E$33,FALSE) | G52: =SUM(C52:F52)
B53: Human: DS | C53: =COUNTIFS('R3 Chunk Dominant'!$B$2:$B$33,"DS",'R3 Chunk Dominant'!$D$2:$D$33,"PS",'R3 Chunk Dominant'!$C$2:$C$33,FALSE,'R3 Chunk Dominant'!$E$2:$E$33,FALSE) | D53: =COUNTIFS('R3 Chunk Dominant'!$B$2:$B$33,"DS",'R3 Chunk Dominant'!$D$2:$D$33,"DS",'R3 Chunk Dominant'!$C$2:$C$33,FALSE,'R3 Chunk Dominant'!$E$2:$E$33,FALSE) | E53: =COUNTIFS('R3 Chunk Dominant'!$B$2:$B$33,"DS",'R3 Chunk Dominant'!$D$2:$D$33,"PPG",'R3 Chunk Dominant'!$C$2:$C$33,FALSE,'R3 Chunk Dominant'!$E$2:$E$33,FALSE) | F53: =COUNTIFS('R3 Chunk Dominant'!$B$2:$B$33,"DS",'R3 Chunk Dominant'!$D$2:$D$33,"SC",'R3 Chunk Dominant'!$C$2:$C$33,FALSE,'R3 Chunk Dominant'!$E$2:$E$33,FALSE) | G53: =SUM(C53:F53)
B54: Human: PPG | C54: =COUNTIFS('R3 Chunk Dominant'!$B$2:$B$33,"PPG",'R3 Chunk Dominant'!$D$2:$D$33,"PS",'R3 Chunk Dominant'!$C$2:$C$33,FALSE,'R3 Chunk Dominant'!$E$2:$E$33,FALSE) | D54: =COUNTIFS('R3 Chunk Dominant'!$B$2:$B$33,"PPG",'R3 Chunk Dominant'!$D$2:$D$33,"DS",'R3 Chunk Dominant'!$C$2:$C$33,FALSE,'R3 Chunk Dominant'!$E$2:$E$33,FALSE) | E54: =COUNTIFS('R3 Chunk Dominant'!$B$2:$B$33,"PPG",'R3 Chunk Dominant'!$D$2:$D$33,"PPG",'R3 Chunk Dominant'!$C$2:$C$33,FALSE,'R3 Chunk Dominant'!$E$2:$E$33,FALSE) | F54: =COUNTIFS('R3 Chunk Dominant'!$B$2:$B$33,"PPG",'R3 Chunk Dominant'!$D$2:$D$33,"SC",'R3 Chunk Dominant'!$C$2:$C$33,FALSE,'R3 Chunk Dominant'!$E$2:$E$33,FALSE) | G54: =SUM(C54:F54)
B55: Human: SC | C55: =COUNTIFS('R3 Chunk Dominant'!$B$2:$B$33,"SC",'R3 Chunk Dominant'!$D$2:$D$33,"PS",'R3 Chunk Dominant'!$C$2:$C$33,FALSE,'R3 Chunk Dominant'!$E$2:$E$33,FALSE) | D55: =COUNTIFS('R3 Chunk Dominant'!$B$2:$B$33,"SC",'R3 Chunk Dominant'!$D$2:$D$33,"DS",'R3 Chunk Dominant'!$C$2:$C$33,FALSE,'R3 Chunk Dominant'!$E$2:$E$33,FALSE) | E55: =COUNTIFS('R3 Chunk Dominant'!$B$2:$B$33,"SC",'R3 Chunk Dominant'!$D$2:$D$33,"PPG",'R3 Chunk Dominant'!$C$2:$C$33,FALSE,'R3 Chunk Dominant'!$E$2:$E$33,FALSE) | F55: =COUNTIFS('R3 Chunk Dominant'!$B$2:$B$33,"SC",'R3 Chunk Dominant'!$D$2:$D$33,"SC",'R3 Chunk Dominant'!$C$2:$C$33,FALSE,'R3 Chunk Dominant'!$E$2:$E$33,FALSE) | G55: =SUM(C55:F55)
...

Sheet Report Key
A1: Code | B1: Report ID | C1: Human rows | D1: AI rows | E1: Matched chunks | F1: Coded by both
A2: R1 | B2: 363466802_2021 | C2: 403 | D2: 337 | E2: 337 | F2: 161
A3: R2 | B3: 382023395_2022 | C3: 393 | D3: 335 | E3: 333 | F3: 113
A4: R3 | B4: 25-1650208_2021 | C4: 160 | D4: 114 | E4: 114 | F4: 32

Sheet Pooled Agreement
B2: Pooled chunk-level agreement — all reports combined
B3: Confusion matrix is the SUM of each report’s own "Agreement" sheet matrix (live cross-sheet formulas), not a separately hardcoded pooled count — so it stays correct if any report’s chunk data changes. N = 306 chunks coded by both coders, pooled across 3 reports.
B5: A. Full sample (pooled across all reports)
C6: AI: PS | D6: AI: DS | E6: AI: PPG | F6: AI: SC | G6: Row total
B7: Human: PS | C7: ='R1 Agreement'!C9+'R2 Agreement'!C9+'R3 Agreement'!C9 | D7: ='R1 Agreement'!D9+'R2 Agreement'!D9+'R3 Agreement'!D9 | E7: ='R1 Agreement'!E9+'R2 Agreement'!E9+'R3 Agreement'!E9 | F7: ='R1 Agreement'!F9+'R2 Agreement'!F9+'R3 Agreement'!F9 | G7: =SUM(C7:F7)
B8: Human: DS | C8: ='R1 Agreement'!C10+'R2 Agreement'!C10+'R3 Agreement'!C10 | D8: ='R1 Agreement'!D10+'R2 Agreement'!D10+'R3 Agreement'!D10 | E8: ='R1 Agreement'!E10+'R2 Agreement'!E10+'R3 Agreement'!E10 | F8: ='R1 Agreement'!F10+'R2 Agreement'!F10+'R3 Agreement'!F10 | G8: =SUM(C8:F8)
B9: Human: PPG | C9: ='R1 Agreement'!C11+'R2 Agreement'!C11+'R3 Agreement'!C11 | D9: ='R1 Agreement'!D11+'R2 Agreement'!D11+'R3 Agreement'!D11 | E9: ='R1 Agreement'!E11+'R2 Agreement'!E11+'R3 Agreement'!E11 | F9: ='R1 Agreement'!F11+'R2 Agreement'!F11+'R3 Agreement'!F11 | G9: =SUM(C9:F9)
B10: Human: SC | C10: ='R1 Agreement'!C12+'R2 Agreement'!C12+'R3 Agreement'!C12 | D10: ='R1 Agreement'!D12+'R2 Agreement'!D12+'R3 Agreement'!D12 | E10: ='R1 Agreement'!E12+'R2 Agreement'!E12+'R3 Agreement'!E12 | F10: ='R1 Agreement'!F12+'R2 Agreement'!F12+'R3 Agreement'!F12 | G10: =SUM(C10:F10)
B11: Col total | C11: =SUM(C7:C10) | D11: =SUM(D7:D10) | E11: =SUM(E7:E10) | F11: =SUM(F7:F10) | G11: =SUM(G7:G10)
B13: Expected under independence
C14: =$G7*C$11/$G$11 | D14: =$G7*D$11/$G$11 | E14: =$G7*E$11/$G$11 | F14: =$G7*F$11/$G$11
C15: =$G8*C$11/$G$11 | D15: =$G8*D$11/$G$11 | E15: =$G8*E$11/$G$11 | F15: =$G8*F$11/$G$11
C16: =$G9*C$11/$G$11 | D16: =$G9*D$11/$G$11 | E16: =$G9*E$11/$G$11 | F16: =$G9*F$11/$G$11
C17: =$G10*C$11/$G$11 | D17: =$G10*D$11/$G$11 | E17: =$G10*E$11/$G$11 | F17: =$G10*F$11/$G$11
B19: Raw agreement | G19: =(C7+D8+E9+F10)/G11
B21: PRIMARY — standard (nominal, unweighted) Cohen’s kappa
C22: 0 | D22: 1 | E22: 1 | F22: 1
C23: 1 | D23: 0 | E23: 1 | F23: 1
C24: 1 | D24: 1 | E24: 0 | F24: 1
C25: 1 | D25: 1 | E25: 1 | F25: 0
B27: Kappa | G27: =1-SUMPRODUCT(C22:F25,C7:F10)/SUMPRODUCT(C22:F25,C14:F17)
B30: RETIRED — quadratic ordinal weights (no theoretical basis; kept for comparison)
C31: 0 | D31: 1 | E31: 4 | F31: 9
C32: 1 | D32: 0 | E32: 1 | F32: 4
C33: 4 | D33: 1 | E33: 0 | F33: 1
C34: 9 | D34: 4 | E34: 1 | F34: 0
B36: Kappa | G36: =1-SUMPRODUCT(C31:F34,C7:F10)/SUMPRODUCT(C31:F34,C14:F17)
B39: RETIRED — linear ordinal weights (same caveat)
C40: 0 | D40: 1 | E40: 2 | F40: 3
C41: 1 | D41: 0 | E41: 1 | F41: 2
C42: 2 | D42: 1 | E42: 0 | F42: 1
C43: 3 | D43: 2 | E43: 1 | F43: 0
B45: Kappa | G45: =1-SUMPRODUCT(C40:F43,C7:F10)/SUMPRODUCT(C40:F43,C14:F17)
B48: B. Sensitivity — ties excluded (pooled)
C49: AI: PS | D49: AI: DS | E49: AI: PPG | F49: AI: SC | G49: Row total
B50: Human: PS | C50: ='R1 Agreement'!C52+'R2 Agreement'!C52+'R3 Agreement'!C52 | D50: ='R1 Agreement'!D52+'R2 Agreement'!D52+'R3 Agreement'!D52 | E50: ='R1 Agreement'!E52+'R2 Agreement'!E52+'R3 Agreement'!E52 | F50: ='R1 Agreement'!F52+'R2 Agreement'!F52+'R3 Agreement'!F52 | G50: =SUM(C50:F50)
B51: Human: DS | C51: ='R1 Agreement'!C53+'R2 Agreement'!C53+'R3 Agreement'!C53 | D51: ='R1 Agreement'!D53+'R2 Agreement'!D53+'R3 Agreement'!D53 | E51: ='R1 Agreement'!E53+'R2 Agreement'!E53+'R3 Agreement'!E53 | F51: ='R1 Agreement'!F53+'R2 Agreement'!F53+'R3 Agreement'!F53 | G51: =SUM(C51:F51)
B52: Human: PPG | C52: ='R1 Agreement'!C54+'R2 Agreement'!C54+'R3 Agreement'!C54 | D52: ='R1 Agreement'!D54+'R2 Agreement'!D54+'R3 Agreement'!D54 | E52: ='R1 Agreement'!E54+'R2 Agreement'!E54+'R3 Agreement'!E54 | F52: ='R1 Agreement'!F54+'R2 Agreement'!F54+'R3 Agreement'!F54 | G52: =SUM(C52:F52)
B53: Human: SC | C53: ='R1 Agreement'!C55+'R2 Agreement'!C55+'R3 Agreement'!C55 | D53: ='R1 Agreement'!D55+'R2 Agreement'!D55+'R3 Agreement'!D55 | E53: ='R1 Agreement'!E55+'R2 Agreement'!E55+'R3 Agreement'!E55 | F53: ='R1 Agreement'!F55+'R2 Agreement'!F55+'R3 Agreement'!F55 | G53: =SUM(C53:F53)
B54: Col total | C54: =SUM(C50:C53) | D54: =SUM(D50:D53) | E54: =SUM(E50:E53) | F54: =SUM(F50:F53) | G54: =SUM(G50:G53)
...

Sheet Flexible Agreement
B2: Alternative agreement measure — chunk-flexible vicinity (permutation-based)
B3: A chunk is a "flexible match" if the two coders’ dominant picks agree, OR either coder’s dominant pick is in the OTHER coder’s own chunk-level top-2 set (points-derived, per chunk, no global category order assumed). Because this uses both coders’ per-chunk rankings jointly, there is no closed-form chance-correction formula; chance is estimated by permutation (randomly re-pairing AI chunks against human chunks many times, holding each side’s own per-chunk data fixed). kappa_flexible = (observed − permutation chance) / (1 − permutation chance). The sanity-check columns apply the identical permutation to STRICT matching, which should closely reproduce the closed-form standard kappa.
B6: Report | C6: N | D6: # permutations | E6: seed | F6: Observed flexible rate | G6: Permutation chance rate | H6: kappa_flexible | I6: # flexible-only chunks | J6: Sanity: permutation strict chance | K6: Sanity: kappa via permutation | L6: Sanity: kappa closed-form
B7: 363466802_2021 | C7: 161 | D7: 3000 | E7: 0 | F7: 0.95652174 | G7: 0.65704762 | H7: 0.87322362 | I7: 37 | J7: 0.39723395 | K7: 0.54660365 | L7: 0.54726146
B8: 382023395_2022 | C8: 113 | D8: 3000 | E8: 0 | F8: 0.96460177 | G8: 0.60108555 | H8: 0.91126361 | I8: 37 | J8: 0.2760118 | K8: 0.49884286 | L8: 0.49913514
B9: 25-1650208_2021 | C9: 32 | D9: 3000 | E9: 0 | F9: 0.96875 | G9: 0.63583333 | H9: 0.91418764 | I9: 11 | J9: 0.30659375 | K9: 0.45919149 | L9: 0.45685997
B10: POOLED (all reports) | C10: 306 | D10: 3000 | E10: 0 | F10: 0.96078431 | G10: 0.58440741 | H10: 0.90563911 | I10: 85 | J10: 0.28020588 | K10: 0.55960537 | L10: 0.55935927
B12: Sanity check reads: the permutation-based strict kappa (col. K) should closely match the closed-form standard kappa from the Agreement sheets (col. L) — confirms the permutation procedure itself is unbiased.

Sheet Report Profile
B2: Report-level logic profile — ALL coded chunks, independent of chunk matching
B3: Unlike the Agreement sheets (restricted to chunks coded by BOTH coders), this uses every row either coder coded in their own raw file, so each coder’s overall document-level logic-frequency profile is not constrained by what the other coder happened to also code. TVD = total variation distance between the human and AI proportion vectors (0.5×Σ|p−q|); cosine = cosine similarity between them.
